[2024-10-19T19:55:56.287+0000] {taskinstance.py:1979} INFO - Dependencies all met for dep_context=non-requeueable deps ti=<TaskInstance: dbt_dag.run_dbt_model manual__2024-10-19T19:54:50.916621+00:00 [queued]>
[2024-10-19T19:55:56.295+0000] {taskinstance.py:1979} INFO - Dependencies all met for dep_context=requeueable deps ti=<TaskInstance: dbt_dag.run_dbt_model manual__2024-10-19T19:54:50.916621+00:00 [queued]>
[2024-10-19T19:55:56.295+0000] {taskinstance.py:2193} INFO - Starting attempt 2 of 3
[2024-10-19T19:55:56.307+0000] {taskinstance.py:2214} INFO - Executing <Task(BashOperator): run_dbt_model> on 2024-10-19 19:54:50.916621+00:00
[2024-10-19T19:55:56.310+0000] {standard_task_runner.py:60} INFO - Started process 271 to run task
[2024-10-19T19:55:56.313+0000] {standard_task_runner.py:87} INFO - Running: ['airflow', 'tasks', 'run', 'dbt_dag', 'run_dbt_model', 'manual__2024-10-19T19:54:50.916621+00:00', '--job-id', '18', '--raw', '--subdir', 'DAGS_FOLDER/marketing_dbt_transformation.py', '--cfg-path', '/tmp/tmpjua_ymhk']
[2024-10-19T19:55:56.314+0000] {standard_task_runner.py:88} INFO - Job 18: Subtask run_dbt_model
[2024-10-19T19:55:56.327+0000] {logging_mixin.py:188} WARNING - /home/airflow/.local/lib/python3.9/site-packages/airflow/settings.py:194 DeprecationWarning: The sql_alchemy_conn option in [core] has been moved to the sql_alchemy_conn option in [database] - the old setting has been used, but please update your config.
[2024-10-19T19:55:56.363+0000] {task_command.py:423} INFO - Running <TaskInstance: dbt_dag.run_dbt_model manual__2024-10-19T19:54:50.916621+00:00 [running]> on host finpro-airflow-scheduler
[2024-10-19T19:55:56.427+0000] {taskinstance.py:2510} INFO - Exporting env vars: AIRFLOW_CTX_DAG_OWNER='airflow' AIRFLOW_CTX_DAG_ID='dbt_dag' AIRFLOW_CTX_TASK_ID='run_dbt_model' AIRFLOW_CTX_EXECUTION_DATE='2024-10-19T19:54:50.916621+00:00' AIRFLOW_CTX_TRY_NUMBER='2' AIRFLOW_CTX_DAG_RUN_ID='manual__2024-10-19T19:54:50.916621+00:00'
[2024-10-19T19:55:56.429+0000] {subprocess.py:63} INFO - Tmp dir root location: /tmp
[2024-10-19T19:55:56.430+0000] {subprocess.py:75} INFO - Running command: ['/usr/bin/bash', '-c', 'dbt run --models customers_stg.sql orders_stg.sql order_items_stg.sql']
[2024-10-19T19:55:56.437+0000] {subprocess.py:86} INFO - Output:
[2024-10-19T19:55:56.438+0000] {subprocess.py:93} INFO - /usr/bin/bash: line 1: dbt: command not found
[2024-10-19T19:55:56.439+0000] {subprocess.py:97} INFO - Command exited with return code 127
[2024-10-19T19:55:56.449+0000] {taskinstance.py:2728} ERROR - Task failed with exception
Traceback (most recent call last):
  File "/home/airflow/.local/lib/python3.9/site-packages/airflow/models/taskinstance.py", line 444, in _execute_task
    result = _execute_callable(context=context, **execute_callable_kwargs)
  File "/home/airflow/.local/lib/python3.9/site-packages/airflow/models/taskinstance.py", line 414, in _execute_callable
    return execute_callable(context=context, **execute_callable_kwargs)
  File "/home/airflow/.local/lib/python3.9/site-packages/airflow/operators/bash.py", line 212, in execute
    raise AirflowException(
airflow.exceptions.AirflowException: Bash command failed. The command returned a non-zero exit code 127.
[2024-10-19T19:55:56.452+0000] {taskinstance.py:1149} INFO - Marking task as UP_FOR_RETRY. dag_id=dbt_dag, task_id=run_dbt_model, execution_date=20241019T195450, start_date=20241019T195556, end_date=20241019T195556
[2024-10-19T19:55:56.461+0000] {standard_task_runner.py:107} ERROR - Failed to execute job 18 for task run_dbt_model (Bash command failed. The command returned a non-zero exit code 127.; 271)
[2024-10-19T19:55:56.485+0000] {local_task_job_runner.py:234} INFO - Task exited with return code 1
[2024-10-19T19:55:56.500+0000] {taskinstance.py:3309} INFO - 0 downstream tasks scheduled from follow-on schedule check
