[2024-10-19T19:54:54.009+0000] {taskinstance.py:1979} INFO - Dependencies all met for dep_context=non-requeueable deps ti=<TaskInstance: dbt_dag.run_dbt_model scheduled__2023-05-14T00:00:00+00:00 [queued]>
[2024-10-19T19:54:54.016+0000] {taskinstance.py:1979} INFO - Dependencies all met for dep_context=requeueable deps ti=<TaskInstance: dbt_dag.run_dbt_model scheduled__2023-05-14T00:00:00+00:00 [queued]>
[2024-10-19T19:54:54.016+0000] {taskinstance.py:2193} INFO - Starting attempt 1 of 2
[2024-10-19T19:54:54.037+0000] {taskinstance.py:2214} INFO - Executing <Task(BashOperator): run_dbt_model> on 2023-05-14 00:00:00+00:00
[2024-10-19T19:54:54.041+0000] {standard_task_runner.py:60} INFO - Started process 255 to run task
[2024-10-19T19:54:54.044+0000] {standard_task_runner.py:87} INFO - Running: ['airflow', 'tasks', 'run', 'dbt_dag', 'run_dbt_model', 'scheduled__2023-05-14T00:00:00+00:00', '--job-id', '16', '--raw', '--subdir', 'DAGS_FOLDER/marketing_dbt_transformation.py', '--cfg-path', '/tmp/tmpzr97d7l8']
[2024-10-19T19:54:54.046+0000] {standard_task_runner.py:88} INFO - Job 16: Subtask run_dbt_model
[2024-10-19T19:54:54.059+0000] {logging_mixin.py:188} WARNING - /home/airflow/.local/lib/python3.9/site-packages/airflow/settings.py:194 DeprecationWarning: The sql_alchemy_conn option in [core] has been moved to the sql_alchemy_conn option in [database] - the old setting has been used, but please update your config.
[2024-10-19T19:54:54.092+0000] {task_command.py:423} INFO - Running <TaskInstance: dbt_dag.run_dbt_model scheduled__2023-05-14T00:00:00+00:00 [running]> on host finpro-airflow-scheduler
[2024-10-19T19:54:54.172+0000] {taskinstance.py:2510} INFO - Exporting env vars: AIRFLOW_CTX_DAG_OWNER='airflow' AIRFLOW_CTX_DAG_ID='dbt_dag' AIRFLOW_CTX_TASK_ID='run_dbt_model' AIRFLOW_CTX_EXECUTION_DATE='2023-05-14T00:00:00+00:00' AIRFLOW_CTX_TRY_NUMBER='1' AIRFLOW_CTX_DAG_RUN_ID='scheduled__2023-05-14T00:00:00+00:00'
[2024-10-19T19:54:54.173+0000] {subprocess.py:63} INFO - Tmp dir root location: /tmp
[2024-10-19T19:54:54.174+0000] {subprocess.py:75} INFO - Running command: ['/usr/bin/bash', '-c', 'dbt run --models customers_stg.sql orders_stg.sql order_items_stg.sql']
[2024-10-19T19:54:54.181+0000] {subprocess.py:86} INFO - Output:
[2024-10-19T19:54:54.182+0000] {subprocess.py:93} INFO - /usr/bin/bash: line 1: dbt: command not found
[2024-10-19T19:54:54.182+0000] {subprocess.py:97} INFO - Command exited with return code 127
[2024-10-19T19:54:54.192+0000] {taskinstance.py:2728} ERROR - Task failed with exception
Traceback (most recent call last):
  File "/home/airflow/.local/lib/python3.9/site-packages/airflow/models/taskinstance.py", line 444, in _execute_task
    result = _execute_callable(context=context, **execute_callable_kwargs)
  File "/home/airflow/.local/lib/python3.9/site-packages/airflow/models/taskinstance.py", line 414, in _execute_callable
    return execute_callable(context=context, **execute_callable_kwargs)
  File "/home/airflow/.local/lib/python3.9/site-packages/airflow/operators/bash.py", line 212, in execute
    raise AirflowException(
airflow.exceptions.AirflowException: Bash command failed. The command returned a non-zero exit code 127.
[2024-10-19T19:54:54.195+0000] {taskinstance.py:1149} INFO - Marking task as UP_FOR_RETRY. dag_id=dbt_dag, task_id=run_dbt_model, execution_date=20230514T000000, start_date=20241019T195454, end_date=20241019T195454
[2024-10-19T19:54:54.206+0000] {standard_task_runner.py:107} ERROR - Failed to execute job 16 for task run_dbt_model (Bash command failed. The command returned a non-zero exit code 127.; 255)
[2024-10-19T19:54:54.216+0000] {local_task_job_runner.py:234} INFO - Task exited with return code 1
[2024-10-19T19:54:54.237+0000] {taskinstance.py:3309} INFO - 0 downstream tasks scheduled from follow-on schedule check
